Workbook

Sheet FRONT 
A1: BRANCH : | H1: RIDER DELIVERY SUMMARY
A2: DATE : | B2: 46287 | E2: SYSTEM DATE: | F2: 46287 | H2: RIDER NAME (1-4) | I2: PRODUCT AMOUNT | J2: DEL FEE | K2: SUBTOTAL | L2: INCENTIVES | M2: TOTAL | N2: REMARKS
H3: JAIME | I3: =DELIVERY!D29+DELIVERY!L29 -> 4650 | J3: =DELIVERY!E29+DELIVERY!M29 -> 137 | K3: =I3+J3 -> 4787 | M3: =K3-L3 -> 4787
A4: SALES Breakdown (CASH) | E4: Number of products | H4: NAME | I4: =DELIVERY!D59+DELIVERY!L59 -> 0 | J4: =DELIVERY!E59+DELIVERY!M59 -> 0 | K4: =I4+J4 -> 0 | M4: =K4-L4 -> 0
B5: Walk in | C5: ='WALK IN'!D30 -> 3375 | E5: Walk-in: | F5: ='WALK IN'!C30+'WALK IN'!I30 -> 8 | I5: 0 | J5: 0 | K5: =I5+J5 -> 0 | M5: =K5-L5 -> 0
B6: Delivery | C6: =DELIVERY!D29+DELIVERY!D59+DELIVERY!D93+DELIVERY!D126 -> 0 | E6: Delivery: | F6: =DELIVERY!C29+DELIVERY!K29+DELIVERY!C59+DELIVERY!K59 -> 4 | I6: 0 | J6: 0 | K6: =I6+J6 -> 0 | M6: =K6-L6 -> 0
B7: Franchise | C7: ='WALK IN'!D55 -> 0 | E7: Franchise: | F7: ='WALK IN'!C55+'WALK IN'!I55+DELIVERY!C93+DELIVERY!K93+SHIPPING!C46 -> 0
B8: Prothin Dealer | C8: ='WALK IN'!D83 -> 0 | E8: Prothin Dealers: | F8: ='WALK IN'!C83+'WALK IN'!I83+DELIVERY!C126+DELIVERY!K126+SHIPPING!K46 -> 0
B9: Agent (Cash) | C9: ='WALK IN'!D111+DELIVERY!D159 -> 0 | E9: Shipping: | F9: =SHIPPING!C19+SHIPPING!K19 -> 0 | H9: Total: | I9: =I3+I4+I5+I6 -> 4650 | J9: =J3+J4+J5+J6 -> 137 | K9: =K3+K4+K5+K6 -> 4787 | L9: =SUM(L3:L8) -> 0 | M9: =SUM(M3:M8) -> 4787
B10: Delivery Fee | C10: =DELIVERY!E29+DELIVERY!E59+DELIVERY!E159 -> 0 | E10: Apparels: | F10: 0
B11: SUBTOTAL | C11: =C5+C6++C7+C8+C10 -> 3375 | E11: Equipment: | F11: 0 | H11: MONEY BREAKDOWN | J11: Quantity | L11: EXPENSES
E12: Agent: | F12: ='WALK IN'!C111+'WALK IN'!I111+DELIVERY!C159+DELIVERY!K159+SHIPPING!C74 -> 0 | H12: 1000 | I12: X | L12: NAME | M12: PARTICULAR/S | N12: AMOUNT
B13: Credit Card (Walk In) | C13: ='CREDIT CARD'!E21 -> 0 | H13: 500 | I13: X | L13: Rent
B14: Credit Card (Delivery) | C14: ='CREDIT CARD'!E74+'CREDIT CARD'!E99+'CREDIT CARD'!E124 -> 0 | H14: 200 | I14: X | L14: Meralco
B15: Credit Card (Agent) | C15: ='CREDIT CARD'!E49 -> 0 | H15: 100 | I15: X | L15: Internet (Globe or Royal cab)
B16: Walk in (Online) | C16: ='WALK IN'!J30 -> 2300 | E16: Delivery Fee (Online) | F16: =DELIVERY!E29+DELIVERY!M29+DELIVERY!E93+DELIVERY!M93+DELIVERY!E126+DELIVERY!M126 -> 137 | H16: 50 | I16: X | L16: Water Bills
B17: Walk in (Online) - Franchise | C17: ='WALK IN'!$J$55 -> 0 | E17: Delivery Fee (Credit Card) | F17: ='CREDIT CARD'!F21 -> 0 | H17: 20 | I17: X | L17: INCENTIVES ETC. | N17: 200
B18: Walk in (Online) - Prothin Dealer | C18: ='WALK IN'!$J$83 -> 0 | E18: Franchise (Online) | H18: 10 | I18: X | L18: Load for Store CP
B19: Walk in (Online) - Agent | C19: ='WALK IN'!J111 -> 0 | E19: Prothin Dealer (Online) | F19: =DELIVERY!$L$126 -> 0 | H19: 5 | I19: X | L19: ABONO LALAMOVE | N19: 137
B20: Delivery (Online) | C20: =DELIVERY!$L$29 -> 4650 | E20: Shipping Fee | F20: =SHIPPING!E19+SHIPPING!E46+SHIPPING!M46 -> 0 | H20: 1 | I20: X
B21: Delivery (Online) - Franchise | C21: =DELIVERY!$L$93 -> 0 | E21: Agent (Online) | F21: =DELIVERY!E159+DELIVERY!M159+SHIPPING!E74 -> 0
B22: Delivery (Online) Prothin Dealer | C22: =DELIVERY!$L$126 -> 0 | E22: TOTAL | F22: =SUM(F16:F21) -> 137
B23: Delivery (Online) Agent | C23: =DELIVERY!L159 -> 0 | H23: check payment
B24: Shipping (LBC/LALAMOVE) | C24: =SHIPPING!D19 -> 0 | H24: TOTAL | K24: =SUM(K12:K23) -> 0 | N24: =SUM(N13:N23) -> 337
B25: Shipping - Franchise | C25: =SHIPPING!D46 -> 0
B26: Shipping - Prothin Dealer | C26: =SHIPPING!L46 -> 0
B27: Shipping - Agent | C27: =SHIPPING!D74 -> 0
B28: Shipping (Shopee/Lazada) | C28: =SHIPPING!M19 -> 0 | L28: OTHERS:
B29: TOTAL ONLINE, CC & SHIPPING | C29: =SUM(C13:C28) -> 6950 | H29: RIDER/DRIVER EXPENSE | L29: lalamove to warehouse
H30: NAME : | I30: PARTICULAR/S | J30: AMOUNT | L30: creditcard terminal
B31: TOTAL WALK IN : | D31: =C5+C13+C16 -> 5675
B32: (CASH,CC, AND ONLINE)
B33: TOTAL DELIVERY : | D33: =C6+C14+C20 -> 4650
B34: (CASH,CC, AND ONLINE)
B35: TOTAL SHIPPING : | D35: =C24+C28 -> 0
B36: (CASH,CC, AND ONLINE)
B37: TOTAL FRANCHISE : | D37: =C7+C25+C17+C21 -> 0 | L37: TOTAL OTHER EXP: | N37: =SUM(N29:N36) -> 0
B38: (CASH AND ONLINE)
B39: TOTAL PROTHIN DEALER : | D39: =C8+C22+C26+C18 -> 0
B40: (CASH AND ONLINE)
...

Sheet WALK IN
A1: WALK IN (CASH) | G1: WALK IN (ONLINE)
A2: DAILY PRODUCT | G2: DAILY PRODUCT
A3: DATE: | B3: 46287 | G3: DATE: | H3: 46287
A4: BRANCH: | B4: Dasma Branch | G4: BRANCH: | H4: Dasma Branch
A5: DR#/ SI # | B5: ITEMS | C5: QTY | D5: AMOUNT | E5: REMARKS | G5: DR#/ SI # | H5: ITEMS | I5: QTY | J5: AMOUNT | K5: REMARKS
A6: 15246 | B6: Prothin Whey Isolate 60s | C6: 1 | D6: 3000 | G6: 15248 | H6: Muscle Tech Mass Extreme 6lbs | I6: 1 | J6: 2100
B7: Gws plain Text | C7: 1 | D7: 0 | H7: Promatrix Shaker | I7: 1 | J7: 200
B8: Plastic L | C8: 1 | D8: 0 | H8: Plastic L | I8: 1 | J8: 0
A9: 15247 | B9: HYDR 8 15 Serving | C9: 1 | D9: 375
B10: Plastic M | C10: 1 | D10: 0
B30: TOTAL | C30: =SUM(C6:C29) -> 5 | D30: =SUM(D6:D29) -> 3375 | H30: TOTAL | I30: =SUM(I6:I29) -> 3 | J30: =SUM(J6:J29) -> 2300
A33: WALK IN (FRANCHISE CASH) | G33: WALK IN (FRANCHISE ONLINE)
A34: DAILY PRODUCT | G34: DAILY PRODUCT
A35: DATE: | G35: DATE:
A36: BRANCH: | G36: BRANCH:
A37: DR#/ SI # | B37: ITEMS | C37: QTY | D37: AMOUNT | E37: REMARKS | G37: DR#/ SI # | H37: ITEMS | I37: QTY | J37: AMOUNT | K37: REMARKS
B55: TOTAL | C55: =SUM(C38:C54) -> 0 | D55: =SUM(D38:D54) -> 0 | H55: TOTAL | I55: =SUM(I38:I54) -> 0 | J55: =SUM(J38:J54) -> 0
A58: WALK IN (PROTHIN DEALER CASH) | G58: WALK IN (PROTHIN ONLINE)
A59: DAILY PRODUCT | G59: DAILY PRODUCT
A60: DATE: | B60: 46271 | G60: DATE: | H60: 46271
A61: BRANCH: | B61: Dasma Branch | G61: BRANCH: | H61: Dasma Branch
A62: DR#/ SI # | B62: ITEMS | C62: QTY | D62: AMOUNT | E62: REMARKS | G62: DR#/ SI # | H62: ITEMS | I62: QTY | J62: AMOUNT | K62: REMARKS
B83: TOTAL | C83: =SUM(C63:C82) -> 0 | D83: =SUM(D63:D82) -> 0 | H83: TOTAL | I83: =SUM(I63:I82) -> 0 | J83: =SUM(J63:J82) -> 0
A86: WALK IN ( AGENT CASH ) | G86: WALK IN (AGENT ONLINE)
A87: DAILY PRODUCT | G87: DAILY PRODUCT
A88: DATE: | B88: 46286 | G88: DATE: | H88: 46287
A89: BRANCH: | B89: Dasma Branch | G89: BRANCH: | H89: Dasma Branch
A90: DR#/ SI # | B90: ITEMS | C90: QTY | D90: AMOUNT | E90: REMARKS | G90: DR#/ SI # | H90: ITEMS | I90: QTY | J90: AMOUNT | K90: REMARKS
B111: TOTAL | C111: =SUM(C91:C110) -> 0 | D111: =SUM(D91:D110) -> 0 | H111: TOTAL | I111: =SUM(I91:I110) -> 0 | J111: =SUM(J91:J110) -> 0

Sheet DELIVERY
A1: DELIVERY (CASH) | I1: DELIVERY (ONLINE)
A2: DAILY PRODUCT | I2: DAILY PRODUCT
A3: RIDER 1: | F3: DATE: | G3: 46271 | I3: RIDER 1: | N3: DATE: | O3: 46287
A4: BRANCH | B4: DASMA BRANCH | I4: BRANCH | J4: DASMA BRANCH
A5: DR#/ SI # | B5: ITEMS | C5: QTY | D5: AMOUNT | E5: DEL FEE | F5: TOTAL AMOUNT | G5: REMARKS | I5: DR#/ SI # | J5: ITEMS | K5: QTY | L5: AMOUNT | M5: DEL FEE | N5: TOTAL AMOUNT | O5: REMARKS
I6: 15245 | J6: Prothin Whey Isolate 60s | K6: 1 | L6: 3000 | M6: 137 | N6: 3000
J7: C4 Ripped 30s | K7: 1 | L7: 1650 | N7: 1650
J8: Gws Lettering Shaker | K8: 1 | L8: 0 | N8: 0
J9: Plastic XL | K9: 1 | L9: 0 | N9: 0
B29: TOTAL | C29: =SUM(C6:C28) -> 0 | D29: =SUM(D6:D28) -> 0 | E29: =SUM(E6:E28) -> 0 | F29: =SUM(F6:F28) -> 0 | J29: TOTAL | K29: =SUM(K6:K28) -> 4 | L29: =SUM(L6:L28) -> 4650 | M29: =SUM(M6:M28) -> 137 | N29: =SUM(N6:N28) -> 4650
A31: DELIVERY (CASH) | I31: DELIVERY (ONLINE)
A32: DAILY PRODUCT | I32: DAILY PRODUCT
A33: RIDER 2: | F33: DATE: | I33: RIDER 2: | N33: DATE:
A34: BRANCH | I34: BRANCH
A35: DR#/ SI # | B35: ITEMS | C35: QTY | D35: AMOUNT | E35: DEL FEE | F35: TOTAL AMOUNT | G35: REMARKS | I35: DR#/ SI # | J35: ITEMS | K35: QTY | L35: AMOUNT | M35: DEL FEE | N35: TOTAL AMOUNT | O35: REMARKS
B59: TOTAL | C59: =SUM(C36:C58) -> 0 | D59: =SUM(D36:D58) -> 0 | E59: =SUM(E36:E58) -> 0 | F59: =SUM(F36:F58) -> 0 | J59: TOTAL | K59: =SUM(K36:K58) -> 0 | L59: =SUM(L36:L58) -> 0 | M59: =SUM(M36:M58) -> 0 | N59: =SUM(N36:N58) -> 0
A64: DELIVERY (FRANCHISE CASH) | I64: DELIVERY (FRANCHISE ONLINE)
A65: DAILY PRODUCT | I65: DAILY PRODUCT
A66: DATE: | I66: DATE:
A67: BRANCH | I67: BRANCH
A68: DR#/ SI # | B68: ITEMS | C68: QTY | D68: AMOUNT | E68: DEL FEE | F68: TOTAL AMOUNT | G68: REMARKS | I68: DR#/ SI # | J68: ITEMS | K68: QTY | L68: AMOUNT | M68: DEL FEE | N68: TOTAL AMOUNT | O68: REMARKS
C93: =SUM(C69:C92) -> 0 | D93: =SUM(D69:D92) -> 0 | E93: =SUM(E69:E92) -> 0 | F93: =SUM(F69:F92) -> 0 | K93: =SUM(K69:K92) -> 0 | L93: =SUM(L69:L92) -> 0 | M93: =SUM(M69:M92) -> 0 | N93: =SUM(N69:N92) -> 0
A96: DELIVERY (PROTHIN DEALER CASH) | I96: DELIVERY (PROTHIN DEALER ONLINE)
A97: DAILY PRODUCT | I97: DAILY PRODUCT
A98: DATE: | B98: SEPT, 5 ,2026 | I98: DATE: | J98: 46270
A99: BRANCH | B99: DASMA BRANCH | I99: BRANCH | J99: DASSMA BRANCH
A100: DR#/ SI # | B100: ITEMS | C100: QTY | D100: AMOUNT | E100: DEL FEE | F100: TOTAL AMOUNT | G100: REMARKS | I100: DR#/ SI # | J100: ITEMS | K100: QTY | L100: AMOUNT | M100: DEL FEE | N100: TOTAL AMOUNT | O100: REMARKS
C126: =SUM(C101:C125) -> 0 | D126: =SUM(D101:D125) -> 0 | E126: =SUM(E101:E125) -> 0 | F126: =SUM(F101:F125) -> 0 | K126: =SUM(K101:K125) -> 0 | L126: =SUM(L101:L125) -> 0 | M126: =SUM(M101:M125) -> 0 | N126: =SUM(N101:N125) -> 0
A129: DELIVERY (AGENT CASH) | I129: DELIVERY (AGENT ONLINE)
A130: DAILY PRODUCT | I130: DAILY PRODUCT
A131: DATE: | B131: September 5,2026 | I131: DATE: | J131: September 5 ,2026
A132: BRANCH | B132: DASMA BRANCH | I132: BRANCH | J132: DASMA BRANCH
A133: DR#/ SI # | B133: ITEMS | C133: QTY | D133: AMOUNT | E133: DEL FEE | F133: TOTAL AMOUNT | G133: REMARKS | I133: DR#/ SI # | J133: ITEMS | K133: QTY | L133: AMOUNT | M133: DEL FEE | N133: TOTAL AMOUNT | O133: REMARKS
C159: =SUM(C134:C158) -> 0 | D159: =SUM(D134:D158) -> 0 | E159: =SUM(E134:E158) -> 0 | F159: =SUM(F134:F158) -> 0 | K159: =SUM(K134:K158) -> 0 | L159: =SUM(L134:L158) -> 0 | M159: =SUM(M134:M158) -> 0 | N159: =SUM(N134:N158) -> 0

Sheet SHIPPING
A1: SHIPPING | I1: SHIPPING
A2: (LBC/LALAMOVE) | I2: (SHOPEE/LAZADA)
A3: DATE: | I3: DATE:
A4: BRANCH: | I4: BRANCH:
A5: DR/SI # | B5: ITEMS | C5: QTY | D5: AMOUNT | E5: SF | F5: TOTAL | G5: SHIP EXP | I5: DR/SI # | J5: ITEMS | K5: QTY | L5: AMOUNT | M5: OR INC | N5: CHARGES
C19: =SUM(C6:C18) -> 0 | D19: =SUM(D6:D18) -> 0 | E19: =SUM(E6:E18) -> 0 | G19: =SUM(G6:G18) -> 0 | K19: =SUM(K6:K18) -> 0 | L19: =SUM(L6:L18) -> 0 | M19: =SUM(M6:M18) -> 0 | N19: =SUM(N6:O18) -> 0
A21: SHIPPING | I21: SHIPPING
A22: ( FRANCHISE ) | I22: ( PROTHIN DEALER )
A23: DATE: | I23: DATE:
A24: BRANCH: | I24: BRANCH:
A25: DR/SI # | B25: ITEMS | C25: QTY | D25: AMOUNT | E25: SF | F25: TOTAL | G25: SHIP EXP | I25: DR/SI # | J25: ITEMS | K25: QTY | L25: AMOUNT | M25: SF | N25: TOTAL | O25: SHIP EXP
C46: =SUM(C26:C45) -> 0 | D46: =SUM(D26:D45) -> 0 | E46: =SUM(E26:E45) -> 0 | F46: =SUM(F26:F45) -> 0 | G46: =SUM(G26:G45) -> 0 | K46: =SUM(K26:K45) -> 0 | L46: =SUM(L26:L45) -> 0 | M46: =SUM(M26:M45) -> 0 | N46: =SUM(N26:N45) -> 0 | O46: =SUM(O26:O45) -> 0
A49: SHIPPING
A50: ( AGENT)
A51: DATE:
A52: BRANCH:
A53: DR/SI # | B53: ITEMS | C53: QTY | D53: AMOUNT | E53: SF | F53: TOTAL | G53: SHIP EXP
C74: =SUM(C54:C73) -> 0 | D74: =SUM(D54:D73) -> 0 | E74: =SUM(E54:E73) -> 0 | F74: =SUM(F54:F73) -> 0 | G74: =SUM(G54:G73) -> 0

Sheet CREDIT CARD
A1: CREDIT CARD REPORT (WALK-IN)
A2: DR#/SI# | B2: CUSTOMER NAME | C2: ITEM PURCHASED | D2: QTY | E2: AMOUNT | F2: DEL FEE | G2: TOTAL | H2: MID # | I2: SLIP # | J2: APR CODE | K2: BATCH #
G4: 0
G5: =SUM(E5+F5) -> 0
G8: =SUM(E8+F8) -> 0
G9: =SUM(E9+F9) -> 0
G10: =SUM(E10+F10) -> 0
G11: =SUM(E11+F11) -> 0
G12: =SUM(E12+F12) -> 0
G13: =SUM(E13+F13) -> 0
G14: =SUM(E14+F14) -> 0
G15: =SUM(E15+F15) -> 0
G16: =SUM(E16+F16) -> 0
G17: =SUM(E17+F17) -> 0
G18: =SUM(E18+F18) -> 0
... G20: =SUM(E20+F20) -> 0
D21: =SUM(D3:D20) -> 0 | E21: =SUM(E3:E20) -> 0 | F21: =SUM(F3:F20) -> 0 | G21: =SUM(G3:G20) -> 0
A26: CREDIT CARD REPORT ( AGENT )
A27: DR# | B27: CUSTOMER NAME | C27: ITEM PURCHASED | D27: QTY | E27: AMOUNT | F27: DEL FEE | G27: TOTAL | H27: MID # | I27: SLIP # | J27: APR CODE | K27: BATCH #
G28: =SUM(E28+F28) -> 0
G29: =SUM(E29+F29) -> 0
G30: =SUM(E30+F30) -> 0
G31: =SUM(E31+F31) -> 0
G32: =SUM(E32+F32) -> 0
G33: =SUM(E33+F33) -> 0
G34: =SUM(E34+F34) -> 0
G35: =SUM(E35+F35) -> 0
G36: =SUM(E36+F36) -> 0
G37: =SUM(E37+F37) -> 0
G38: =SUM(E38+F38) -> 0
G39: =SUM(E39+F39) -> 0
... G48: =SUM(E48+F48) -> 0
D49: =SUM(D28:D48) -> 0 | E49: =SUM(E28:E48) -> 0 | F49: =SUM(F28:F48) -> 0 | G49: =SUM(G28:G48) -> 0
A51: CREDIT CARD REPORT (DELIVERY RIDER 1 )
A52: DR# | B52: CUSTOMER NAME | C52: ITEM PURCHASED | D52: QTY | E52: AMOUNT | F52: DEL FEE | G52: TOTAL | H52: MID # | I52: SLIP # | J52: APR CODE | K52: BATCH #
G53: =SUM(E53+F53) -> 0
G54: =SUM(E54+F54) -> 0
G55: =SUM(E55+F55) -> 0
G56: =SUM(E56+F56) -> 0
G57: =SUM(E57+F57) -> 0
...

Sheet RECEIPT TRACKER
A1: RECEIPT TRACKER | I1: Mode of Payment | Q1: .
A2: (MUST PRESENT ALL ORIGINAL YELLOW COPIES) | I2: CASH
A3: *ERASURES IN DR NOT ALLOWED* | I3: AR / PDC
A4: BRANCH: | B4: Dasma Branch | F4: DATE: | G4: 46287 | I4: ONLINE
A5: DR#/ SI # | B5: ITEMS | C5: QTY | D5: AMOUNT | E5: DF | F5: TOTAL | G5: TRANSACTION TYPE | I5: CREDIT CARD
A6: 15245 | B6: Prothin Whey Isolate 60s | C6: 1 | D6: 3000 | E6: 137 | F6: 3000 | G6: ONLINE | I6: CASH AGENT
B7: C4 Ripped 30s | C7: 1 | D7: 1650 | F7: 1650 | I7: AR / PDC AGENT
B8: Gws Lettering Shaker | C8: 1 | D8: 0 | F8: 0 | I8: ONLINE AGENT
B9: Plastic XL | C9: 1 | D9: 0 | F9: 0 | I9: CR. CARD AGENT
A10: 15246 | B10: Prothin Whey Isolate 60s | C10: 1 | D10: 3000 | F10: 3000 | G10: CASH
B11: Gws plain Text | C11: 1 | D11: 0 | F11: 0
B12: Plastic L | C12: 1 | D12: 0 | F12: 0
A13: 15247 | B13: HYDR 8 15 Serving | C13: 1 | D13: 375 | F13: 375 | G13: CASH
